
---------------------------------- log of upload_id(6) & memeber_id(5255) : 2020-03-24 02:19:34.602724 ----------------------------------
출력 메시지:
Requirement already up-to-date: pip in ./dataVenv/lib/python3.8/site-packages (20.0.2)

에러 메시지:
-------------------------------------------------------------------------------------------------------------------------------------------------

---------------------------------- log of upload_id(1) & memeber_id(5255) : 2020-03-24 03:01:30.155837 ----------------------------------
출력 메시지:
Requirement already up-to-date: pip in ./dataVenv/lib/python3.8/site-packages (20.0.2)

에러 메시지:
------------------------------------------------------------------------------------------------------------------------------------------

---------------------------------- log of upload_id(1) & memeber_id(5255) : 2020-03-24 03:07:08.993362 ----------------------------------
출력 메시지:
Requirement already up-to-date: pip in ./dataVenv/lib/python3.8/site-packages (20.0.2)

에러 메시지:
------------------------------------------------------------------------------------------------------------------------------------------

---------------------------------- log of upload_id(1) & memeber_id(5255) : 2020-03-24 03:14:02.223618 ----------------------------------
출력 메시지:
Requirement already up-to-date: pip in ./dataVenv/lib/python3.8/site-packages (20.0.2)

에러 메시지:
------------------------------------------------------------------------------------------------------------------------------------------

---------------------------------- log of upload_id(1) & memeber_id(5255) : 2020-03-24 03:19:38.168450 ----------------------------------
출력 메시지:
Requirement already up-to-date: pip in ./dataVenv/lib/python3.8/site-packages (20.0.2)

에러 메시지:
------------------------------------------------------------------------------------------------------------------------------------------

---------------------------------- log of upload_id(1) & memeber_id(5255) : 2020-03-24 03:20:55.184782 ----------------------------------
출력 메시지:
Requirement already up-to-date: pip in ./dataVenv/lib/python3.8/site-packages (20.0.2)

에러 메시지:
------------------------------------------------------------------------------------------------------------------------------------------

---------------------------------- log of upload_id(1) & memeber_id(5255) : 2020-03-24 03:22:38.193563 ----------------------------------
출력 메시지:
Requirement already up-to-date: pip in ./dataVenv/lib/python3.8/site-packages (20.0.2)

에러 메시지:
------------------------------------------------------------------------------------------------------------------------------------------

---------------------------------- log of upload_id(1) & memeber_id(5255) : 2020-03-24 03:23:33.859214 ----------------------------------
출력 메시지:
Requirement already up-to-date: pip in ./dataVenv/lib/python3.8/site-packages (20.0.2)

에러 메시지:
------------------------------------------------------------------------------------------------------------------------------------------

---------------------------------- log of upload_id(1) & memeber_id(5255) : 2020-03-24 03:24:25.276234 ----------------------------------
출력 메시지:
Requirement already up-to-date: pip in ./dataVenv/lib/python3.8/site-packages (20.0.2)

에러 메시지:
------------------------------------------------------------------------------------------------------------------------------------------

---------------------------------- log of upload_id(1) & memeber_id(5255) : 2020-03-24 03:24:57.568087 ----------------------------------
출력 메시지:
Requirement already up-to-date: pip in ./dataVenv/lib/python3.8/site-packages (20.0.2)

에러 메시지:
------------------------------------------------------------------------------------------------------------------------------------------

---------------------------------- log of upload_id(5) & memeber_id(5255) : 2020-03-24 03:31:34.526217 ----------------------------------
출력 메시지:
Requirement already up-to-date: pip in ./dataVenv/lib/python3.8/site-packages (20.0.2)

에러 메시지:
------------------------------------------------------------------------------------------------------------------------------------------

---------------------------------- log of upload_id(6) & memeber_id(5255) : 2020-03-24 03:35:22.713981 ----------------------------------
출력 메시지:
Requirement already up-to-date: pip in ./dataVenv/lib/python3.8/site-packages (20.0.2)

에러 메시지:
------------------------------------------------------------------------------------------------------------------------------------------

---------------------------------- log of upload_id(7) & memeber_id(5255) : 2020-03-24 03:38:19.608981 ----------------------------------
출력 메시지:
Requirement already up-to-date: pip in ./dataVenv/lib/python3.8/site-packages (20.0.2)

에러 메시지:
------------------------------------------------------------------------------------------------------------------------------------------

---------------------------------- log of upload_id(1) & memeber_id(5255) : 2020-03-24 03:40:39.960319 ----------------------------------
출력 메시지:
Requirement already up-to-date: pip in ./dataVenv/lib/python3.8/site-packages (20.0.2)

에러 메시지:
------------------------------------------------------------------------------------------------------------------------------------------

---------------------------------- log of upload_id(6) & memeber_id(5255) : 2020-03-24 03:44:02.469058 ----------------------------------
출력 메시지:
Requirement already up-to-date: pip in ./dataVenv/lib/python3.8/site-packages (20.0.2)

에러 메시지:
------------------------------------------------------------------------------------------------------------------------------------------

---------------------------------- log of upload_id(7) & memeber_id(5255) : 2020-03-24 03:45:55.573722 ----------------------------------
출력 메시지:
Requirement already up-to-date: pip in ./dataVenv/lib/python3.8/site-packages (20.0.2)

에러 메시지:
------------------------------------------------------------------------------------------------------------------------------------------

---------------------------------- log of upload_id(1) & memeber_id(5255) : 2020-03-24 04:29:44.643655 ----------------------------------
출력 메시지:
Requirement already up-to-date: pip in ./dataVenv/lib/python3.8/site-packages (20.0.2)

에러 메시지:
------------------------------------------------------------------------------------------------------------------------------------------

---------------------------------- log of upload_id(1) & memeber_id(5255) : 2020-03-24 20:41:06.935068 ----------------------------------
출력 메시지:

에러 메시지:
python: can't open file './temp/5255/data/sample_template_01.py': [Errno 2] No such file or directory
------------------------------------------------------------------------------------------------------------------------------------------

---------------------------------- log of upload_id(1) & memeber_id(5255) : 2020-03-24 22:03:43.447583 ----------------------------------
출력 메시지:

에러 메시지:
python: can't open file './temp/5255/data/sample_template_01.py': [Errno 2] No such file or directory
------------------------------------------------------------------------------------------------------------------------------------------

---------------------------------- log of upload_id(1) & memeber_id(5255) : 2020-03-24 22:04:15.321243 ----------------------------------
출력 메시지:

에러 메시지:
python: can't open file './temp/5255/data/sample_template_01.py': [Errno 2] No such file or directory
------------------------------------------------------------------------------------------------------------------------------------------

---------------------------------- log of upload_id(1) & memeber_id(5255) : 2020-03-24 22:09:17.218247 ----------------------------------
출력 메시지:

에러 메시지:
python: can't open file './temp/5255/data/sample_template_01.py': [Errno 2] No such file or directory
------------------------------------------------------------------------------------------------------------------------------------------

---------------------------------- log of upload_id(1) & memeber_id(5255) : 2020-03-24 22:11:01.395093 ----------------------------------
출력 메시지:
Requirement already up-to-date: pip in ./dataVenv/lib/python3.8/site-packages (20.0.2)

에러 메시지:
Traceback (most recent call last):
  File "./temp/5255/data/sample_template_01.py", line 86, in <module>
    exec(fini)
  File "<string>", line 2, in <module>
ModuleNotFoundError: No module named 'reports'
------------------------------------------------------------------------------------------------------------------------------------------

---------------------------------- log of upload_id(1) & memeber_id(5255) : 2020-03-24 22:18:46.075309 ----------------------------------
출력 메시지:
Requirement already up-to-date: pip in ./dataVenv/lib/python3.8/site-packages (20.0.2)

에러 메시지:
------------------------------------------------------------------------------------------------------------------------------------------

---------------------------------- log of upload_id(1) & memeber_id(5255) : 2020-03-24 22:26:13.232356 ----------------------------------
출력 메시지:
Requirement already up-to-date: pip in ./dataVenv/lib/python3.8/site-packages (20.0.2)

에러 메시지:
------------------------------------------------------------------------------------------------------------------------------------------

---------------------------------- log of upload_id(1) & memeber_id(5255) : 2020-03-24 22:27:55.269600 ----------------------------------
출력 메시지:
Requirement already up-to-date: pip in ./dataVenv/lib/python3.8/site-packages (20.0.2)

에러 메시지:
------------------------------------------------------------------------------------------------------------------------------------------
